# 47. 에러처리

## 47.1 에러 처리의 필요성

에러나 예외적인 상황에 대응하지 않으면 프로그램은 강제 종료된다.

## 47.2 try... catch ... finally 문

```jsx
try {
// 실행할 코드(에러가 발생할 가능성이 있는 코드)
} catch (err) {
// try 코드 블록에서 에러가 발생하면 이 코드 블록의 코드가 실행된다. 
// err에는 try 코드 블록에서 발생한 Error 객체가 전달된다.
} finally {
// 에러 발생과 상관없이 반드시 한 번 실행된다.
}
```

try... catch ... finally 문을 실행하면 먼저 try 코드 블록이 실행된다.

try 코드 블록에 포함된 문 중에서 에러가 발생하면 발생한 에러는 catch 문의 err 변수에 전달되고 catch 코드 블록이 실행된다. 

catch문의 err 변수(변수 이름은 무엇이든 상관X)는 try 코드 블록에 포함된 문 중에서 에러가 발생하면 생성
되고 되고 catch 코드 블록에서만 유효하다.

finally 코드 블록은 에러 발생과 상관없이 반드시 한 번 실행된다.

try... catch... finally 문으로 에러를 처리하면 프로그램이 강제 종료되지 않는다.

## 47.3 Error 객체

Error 생성자 함수는 에러 객체를 생성한다. Error 생성자 함수에는 에러를 상세히 설명하는 에러 메시지를
인수로 전달할 수 있다.

![image.png](attachment:8ec66757-29e5-477e-838b-7cffb5d4a8ff:image.png)

## 47.4 throw 문

Error 생성자 함수로 에러 객체를 생성한다고 에러가 발생하는 것은 아니다.

에러를 발생시키려면 try 코드 블록에서 throw 문으로 에러 객체를 던져야 한다.

throw 문의 표현식은 어떤 값이라도 상관없지만 일반적으로 에러 객체를 지정한다. 에러를 던지면 catch 문의 에러 변수가 생성되고 던져진 에러 객체가 할당된다. 그리고 catch 코드 블록이 실행되기 시작한다.

```jsx
 try {
	// 에러 객체를 던지면 catch 코드 블록이 실행되기 시작한다.
	throw new Error('something wrong'); 
} catch (error) {
	console.log(error);
}
```

## 47.5 에러의 전파

에러는 호출자 방향으로 전파된 다. 즉, 콜 스택의 아래 방향(실행 중인 실행 컨텍스트가 푸시되기 직전에 푸시된 실행 컨텍스트 방향)으로 전파된다.

![image.png](attachment:68da5e54-9bd8-453a-8c84-b59bc596e9a3:image.png)

![image.png](attachment:6d603ace-fee2-4d82-9109-ee1c1c55a7e5:image.png)

⚠ 비동기 함수인 setTimeout이나 프로미스 후속 처리 메서드의 콜백 함수는 호출자가 없다. ⚠

setTimeout이나 프로미스 후속 처리 메서드의 콜백 함수는 태스크 큐나 마이크로태스크 큐에 일시 저장되었다가 콜 스택이 비면 이벤트 루프에 의해 콜 스택으로 푸시되어 실행된다. 이때 콜 스택에 푸시된 콜백 함수의 실행 컨텍스트는 콜 스택의 가장 하부에 존재하게 된다. 따라서 에러를 전파할 호출자가 존재하지 않는다.
